Workbook

Sheet 작성안내
A1: 부적집 · 용신 결과 문구 작성 양식
A2: 결과 화면에 나가는 모든 문구를 여기서 채웁니다. 개발은 이 파일 그대로 반영합니다.
A4: 1. 채워야 할 것
A5: 노란색 칸만 채우면 됩니다. 회색 칸은 참고용이니 건드리지 마세요.
A6: 시트 | B6: 개수 | C6: 내용
A7: A_용신선언 | B7: 3개 | C7: 강약(신강/중화/신약)에 따라 용신을 선언하는 문장
A8: B_강약진단 | B8: 3개 | C8: 사주의 기운이 어떤 상태인지 진단하는 첫 문장
A9: C_조후보정 | B9: 2개 | C9: 사주가 춥거나 더울 때만 덧붙는 문장 (평범하면 생략됨)
A10: D_부적처방 | B10: 5개 | C10: 용신 오행별 부적 추천 멘트
A11: E_용신설명 | B11: 5개 | C11: ★신규★ 용신 오행별 상세 설명 + 메타데이터
A12: 합계 18개
A14: 2. 문장 안에서 쓸 수 있는 변수
A15: 아래 표기를 넣으면 사람마다 알맞은 오행 이름으로 자동 치환됩니다.
A16: {용신} | B16: 그 사람에게 필요한 기운 (예: 불)
A17: {희신} | B17: 용신을 도와주는 기운 (예: 나무)
A18: {기신} | B18: 용신을 방해하는 기운 (예: 물)
A19: 예) "{기신}의 기운이 너무 강한 당신!" → "물의 기운이 너무 강한 당신!"
A21: 3. 문구가 조립되는 순서
A22: 네 블록이 이 순서로 이어 붙어 결과 화면에 나갑니다.
A23: B (강약 진단) → A (용신 선언) → C (조후, 있을 때만) → D (부적 처방)
A24: E (용신 설명)은 이 흐름과 별개로, 용신 한자 아래 영역에 들어갑니다.
A26: 4. 작성 시 지켜주세요
A27: 명세서 §11-4 체크리스트
A28: ① 블록끼리 자연스럽게 이어지도록 문장 끝맺음을 통일해주세요. (A는 "~예요.", B는 "~라서," 처럼)
A29: ② C(조후)는 안 나오는 사람도 많습니다. C 없이 B→A→D만 읽어도 말이 되게 써주세요.
A30: ③ A와 D는 둘 다 용신 기반이라 같은 말이 반복되기 쉽습니다. A는 진단, D는 처방으로 역할을 나눠주세요.
A31: ④ 18개 전체가 하나의 관점(유파)으로 통일되어야 합니다.
A32: ⑤ 조합미리보기 시트에서 45가지 실제 문장을 확인할 수 있습니다. 어색한 조합이 없는지 봐주세요.
... A35: 용신이 정해지면 희신·기신은 자동으로 따라옵니다. (수정 불가)
A36: 오행 | B36: 한자 | C36: 구어 명칭 | D36: 희신(돕는 기운) | E36: 기신(방해 기운) | F36: 색 | G36: 방위 | H36: 계절
A37: 목 | B37: 木 | C37: 나무 | D37: 수 | E37: 금 | F37: 청(靑) | G37: 동(東) | H37: 봄
A38: 화 | B38: 火 | C38: 불 | D38: 목 | E38: 수 | F38: 적(赤) | G38: 남(南) | H38: 여름
A39: 토 | B39: 土 | C39: 땅 | D39: 화 | E39: 목 | F39: 황(黃) | G39: 중앙 | H39: 환절기
A40: 금 | B40: 金 | C40: 쇠 | D40: 토 | E40: 화 | F40: 백(白) | G40: 서(西) | H40: 가을
A41: 수 | B41: 水 | C41: 물 | D41: 금 | E41: 토 | F41: 흑(黑) | G41: 북(北) | H41: 겨울

Sheet A_용신선언
A1: A. 용신 선언
A2: 용신이 무엇인지 선언하는 문장입니다. 강약 상태에 따라 3가지로 갈립니다.
A3: 채울 칸: 3개 (노란색)
A5: 키(코드) | B5: 언제 나오나 | C5: 현재 draft 문구 (개발용, 교체 대상) | D5: ✏️ 새 문구 (여기에 작성) | E5: 비고
A6: strong | B6: 기운이 강한 편일 때 (신강) | C6: {기신}의 기운을 잠재우고, 힘을 빼주는 요소가 당신의 용신이다. 엣헴!
A7: mid | B7: 기운이 균형잡혔을 때 (중화) | C7: 모자란 구석을 살짝 채워주는 요소가 당신의 용신이다. 엣헴!
A8: weak | B8: 기운이 약한 편일 때 (신약) | C8: 당신을 북돋아 일으켜주는 요소가 당신의 용신이다. 엣헴!

Sheet B_강약진단
A1: B. 강약 진단
A2: 결과 화면 첫 문장입니다. 사주 기운이 어떤 상태인지 알려줍니다.
A3: 채울 칸: 3개 (노란색)
A5: 키(코드) | B5: 언제 나오나 | C5: 현재 draft 문구 (개발용, 교체 대상) | D5: ✏️ 새 문구 (여기에 작성) | E5: 비고
A6: strong | B6: 기운이 강한 편일 때 (신강) | C6: 뭔가 부족하다기보다는 {기신}의 기운이 너무나 강한 당신!
A7: mid | B7: 기운이 균형잡혔을 때 (중화) | C7: 기운이 크게 치우치지 않아 팽팽하게 균형을 이루는 당신!
A8: weak | B8: 기운이 약한 편일 때 (신약) | C8: 기운이 여려서 든든하게 받쳐줄 힘이 필요한 당신!

Sheet C_조후보정
A1: C. 조후 보정 (조건부)
A2: 사주가 뚜렷하게 춥거나 더울 때만 덧붙습니다. 그렇지 않은 사람에겐 이 문장이 아예 안 나옵니다.
A3: 채울 칸: 2개 (노란색) · '평범(평)'인 사람은 이 블록이 생략되니 따로 쓸 필요 없습니다
A5: 키(코드) | B5: 언제 나오나 | C5: 현재 draft 문구 (개발용, 교체 대상) | D5: ✏️ 새 문구 (여기에 작성) | E5: 비고
A6: cold | B6: 사주가 차가울 때 (한寒) | C6: 게다가 사주가 차게 얼어 있어, 따뜻한 기운이 이 냉기를 녹여줘요.
A7: hot | B7: 사주가 뜨거울 때 (열熱) | C7: 게다가 사주가 뜨겁게 달아 있어, 시원한 기운이 이 열기를 식혀줘요.

Sheet D_부적처방
A1: D. 부적 처방
A2: 마지막 문장입니다. 용신 기운을 담은 부적을 권하는 멘트로, 용신 오행 5가지별로 씁니다.
A3: 채울 칸: 5개 (노란색)
A5: 키(코드) | B5: 언제 나오나 | C5: 현재 draft 문구 (개발용, 교체 대상) | D5: ✏️ 새 문구 (여기에 작성) | E5: 비고
A6: 목 (木) | B6: 용신이 나무일 때 | C6: 쭉쭉 뻗는 나무의 힘으로 숨통을 틔워보는거 어때?
A7: 화 (火) | B7: 용신이 불일 때 | C7: 불의 힘으로 수마를 날려버리는거 어때?
A8: 토 (土) | B8: 용신이 땅일 때 | C8: 든든한 땅의 힘으로 중심을 잡아보는거 어때?
A9: 금 (金) | B9: 용신이 쇠일 때 | C9: 단단한 쇠의 힘으로 딱 끊어내는거 어때?
A10: 수 (水) | B10: 용신이 물일 때 | C10: 흐르는 물의 힘으로 열기를 식혀보는거 어때?

Sheet E_용신설명
A1: E. 용신 오행별 설명 ★신규 추가★
A2: 결과 화면에서 큰 용신 한자 아래에 들어갈 설명입니다. 용신 5가지에 대해 각각 작성해주세요.
A3: 채울 칸: 5행 × 3열 = 15칸 (노란색). 색·방위·계절은 기본값을 넣어뒀으니 필요하면 고쳐주세요.
A5: 용신 | B5: 한자 | C5: 구어 명칭 | D5: ✏️ 제목 (한 줄, 12자 내외) | E5: ✏️ 설명 본문 (2~3문장) | F5: ✏️ 키워드 (쉼표 구분, 3개) | G5: 색 | H5: 방위 | I5: 계절
A6: 목 | B6: 木 | C6: 나무 | G6: 청(靑) | H6: 동(東) | I6: 봄
A7: 화 | B7: 火 | C7: 불 | D7: 밝히고 데우는 불 | E7: 차게 식은 기운을 녹여 몸과 마음에 온기를 되돌려 줍니다. 표현이 살아나고 사람들 앞에 서는 일이 수월해집니다. | F7: 명예, 표현, 열정 | G7: 적(赤) | H7: 남(南) | I7: 여름
A8: 토 | B8: 土 | C8: 땅 | G8: 황(黃) | H8: 중앙 | I8: 환절기
A9: 금 | B9: 金 | C9: 쇠 | G9: 백(白) | H9: 서(西) | I9: 가을
A10: 수 | B10: 水 | C10: 물 | G10: 흑(黑) | H10: 북(北) | I10: 겨울
A12: ※ 화(火) 행에 채워둔 값은 형식 안내용 예시입니다. 실제 문구로 바꿔주세요.

Sheet 조합미리보기
A1: 조합 미리보기 (45가지)
A2: 왼쪽 시트에 문구를 채우면 실제 손님이 보게 될 문장이 여기에 자동으로 조립됩니다. 어색한 조합이 없는지 확인해주세요.
A3: ※ 변수({용신}·{기신}·{희신})는 각 행의 오행으로 치환해 보여줍니다. 이 시트는 확인용이라 채울 칸이 없습니다.
A5: # | B5: 용신 | C5: 강약 | D5: 조후 | E5: 용신 | F5: 희신 | G5: 기신 | H5: 실제로 나가는 문장
A6: 1 | B6: 목(木) | C6: 신강 | D6: 한(寒) | E6: =INDEX(작성안내!$C$37:$C$41,1) | F6: =INDEX(작성안내!$C$37:$C$41,MATCH("수",작성안내!$A$37:$A$41,0)) | G6: =INDEX(작성안내!$C$37:$C$41,MATCH("금",작성안내!$A$37:$A$41,0)) | H6: =IF(TRIM(SUBSTITUTE(SUBSTITUTE(SUBSTITUTE(T(INDEX(B_강약진단!$D$6:$D$8,MATCH("strong",B_강약진단!$A$6:$A$8,0)))&" "&T(INDEX(A_용신선언!$D$6:$D$8,MATCH("strong",A_용신선언!$A$6:$A$8,0)))&" "&T(INDEX(C_조후보정!$D$6:$D$7,MATCH("cold",C_조후보정!$A$6:$A$7,0)))&" "&T(INDEX(D_부적처방!$D$6:$D$10,1)),"{용신}",$E6),"{희신}",$F6),"{기신}",$G6))="","(아직 문구가 채워지지 않았습니다)",TRIM(SUBSTITUTE(SUBSTITUTE(SUBSTITUTE(T(INDEX(B_강약진단!$D$6:$D$8,MATCH("strong",B_강약진단!$A$6:$A$8,0)))&" "&T(INDEX(A_용신선언!$D$6:$D$8,MATCH("strong",A_용신선언!$A$6:$A$8,0)))&" "&T(INDEX(C_조후보정!$D$6:$D$7,MATCH("cold",C_조후보정!$A$6:$A$7,0)))&" "&T(INDEX(D_부적처방!$D$6:$D$10,1)),"{용신}",$E6),"{희신}",$F6),"{기신}",$G6)))
A7: 2 | B7: 목(木) | C7: 신강 | D7: 열(熱) | E7: =INDEX(작성안내!$C$37:$C$41,1) | F7: =INDEX(작성안내!$C$37:$C$41,MATCH("수",작성안내!$A$37:$A$41,0)) | G7: =INDEX(작성안내!$C$37:$C$41,MATCH("금",작성안내!$A$37:$A$41,0)) | H7: =IF(TRIM(SUBSTITUTE(SUBSTITUTE(SUBSTITUTE(T(INDEX(B_강약진단!$D$6:$D$8,MATCH("strong",B_강약진단!$A$6:$A$8,0)))&" "&T(INDEX(A_용신선언!$D$6:$D$8,MATCH("strong",A_용신선언!$A$6:$A$8,0)))&" "&T(INDEX(C_조후보정!$D$6:$D$7,MATCH("hot",C_조후보정!$A$6:$A$7,0)))&" "&T(INDEX(D_부적처방!$D$6:$D$10,1)),"{용신}",$E7),"{희신}",$F7),"{기신}",$G7))="","(아직 문구가 채워지지 않았습니다)",TRIM(SUBSTITUTE(SUBSTITUTE(SUBSTITUTE(T(INDEX(B_강약진단!$D$6:$D$8,MATCH("strong",B_강약진단!$A$6:$A$8,0)))&" "&T(INDEX(A_용신선언!$D$6:$D$8,MATCH("strong",A_용신선언!$A$6:$A$8,0)))&" "&T(INDEX(C_조후보정!$D$6:$D$7,MATCH("hot",C_조후보정!$A$6:$A$7,0)))&" "&T(INDEX(D_부적처방!$D$6:$D$10,1)),"{용신}",$E7),"{희신}",$F7),"{기신}",$G7)))
A8: 3 | B8: 목(木) | C8: 신강 | D8: 평(平) | E8: =INDEX(작성안내!$C$37:$C$41,1) | F8: =INDEX(작성안내!$C$37:$C$41,MATCH("수",작성안내!$A$37:$A$41,0)) | G8: =INDEX(작성안내!$C$37:$C$41,MATCH("금",작성안내!$A$37:$A$41,0)) | H8: =IF(TRIM(SUBSTITUTE(SUBSTITUTE(SUBSTITUTE(T(INDEX(B_강약진단!$D$6:$D$8,MATCH("strong",B_강약진단!$A$6:$A$8,0)))&" "&T(INDEX(A_용신선언!$D$6:$D$8,MATCH("strong",A_용신선언!$A$6:$A$8,0)))&" "&T(INDEX(D_부적처방!$D$6:$D$10,1)),"{용신}",$E8),"{희신}",$F8),"{기신}",$G8))="","(아직 문구가 채워지지 않았습니다)",TRIM(SUBSTITUTE(SUBSTITUTE(SUBSTITUTE(T(INDEX(B_강약진단!$D$6:$D$8,MATCH("strong",B_강약진단!$A$6:$A$8,0)))&" "&T(INDEX(A_용신선언!$D$6:$D$8,MATCH("strong",A_용신선언!$A$6:$A$8,0)))&" "&T(INDEX(D_부적처방!$D$6:$D$10,1)),"{용신}",$E8),"{희신}",$F8),"{기신}",$G8)))
A9: 4 | B9: 목(木) | C9: 중화 | D9: 한(寒) | E9: =INDEX(작성안내!$C$37:$C$41,1) | F9: =INDEX(작성안내!$C$37:$C$41,MATCH("수",작성안내!$A$37:$A$41,0)) | G9: =INDEX(작성안내!$C$37:$C$41,MATCH("금",작성안내!$A$37:$A$41,0)) | H9: =IF(TRIM(SUBSTITUTE(SUBSTITUTE(SUBSTITUTE(T(INDEX(B_강약진단!$D$6:$D$8,MATCH("mid",B_강약진단!$A$6:$A$8,0)))&" "&T(INDEX(A_용신선언!$D$6:$D$8,MATCH("mid",A_용신선언!$A$6:$A$8,0)))&" "&T(INDEX(C_조후보정!$D$6:$D$7,MATCH("cold",C_조후보정!$A$6:$A$7,0)))&" "&T(INDEX(D_부적처방!$D$6:$D$10,1)),"{용신}",$E9),"{희신}",$F9),"{기신}",$G9))="","(아직 문구가 채워지지 않았습니다)",TRIM(SUBSTITUTE(SUBSTITUTE(SUBSTITUTE(T(INDEX(B_강약진단!$D$6:$D$8,MATCH("mid",B_강약진단!$A$6:$A$8,0)))&" "&T(INDEX(A_용신선언!$D$6:$D$8,MATCH("mid",A_용신선언!$A$6:$A$8,0)))&" "&T(INDEX(C_조후보정!$D$6:$D$7,MATCH("cold",C_조후보정!$A$6:$A$7,0)))&" "&T(INDEX(D_부적처방!$D$6:$D$10,1)),"{용신}",$E9),"{희신}",$F9),"{기신}",$G9)))
A10: 5 | B10: 목(木) | C10: 중화 | D10: 열(熱) | E10: =INDEX(작성안내!$C$37:$C$41,1) | F10: =INDEX(작성안내!$C$37:$C$41,MATCH("수",작성안내!$A$37:$A$41,0)) | G10: =INDEX(작성안내!$C$37:$C$41,MATCH("금",작성안내!$A$37:$A$41,0)) | H10: =IF(TRIM(SUBSTITUTE(SUBSTITUTE(SUBSTITUTE(T(INDEX(B_강약진단!$D$6:$D$8,MATCH("mid",B_강약진단!$A$6:$A$8,0)))&" "&T(INDEX(A_용신선언!$D$6:$D$8,MATCH("mid",A_용신선언!$A$6:$A$8,0)))&" "&T(INDEX(C_조후보정!$D$6:$D$7,MATCH("hot",C_조후보정!$A$6:$A$7,0)))&" "&T(INDEX(D_부적처방!$D$6:$D$10,1)),"{용신}",$E10),"{희신}",$F10),"{기신}",$G10))="","(아직 문구가 채워지지 않았습니다)",TRIM(SUBSTITUTE(SUBSTITUTE(SUBSTITUTE(T(INDEX(B_강약진단!$D$6:$D$8,MATCH("mid",B_강약진단!$A$6:$A$8,0)))&" "&T(INDEX(A_용신선언!$D$6:$D$8,MATCH("mid",A_용신선언!$A$6:$A$8,0)))&" "&T(INDEX(C_조후보정!$D$6:$D$7,MATCH("hot",C_조후보정!$A$6:$A$7,0)))&" "&T(INDEX(D_부적처방!$D$6:$D$10,1)),"{용신}",$E10),"{희신}",$F10),"{기신}",$G10)))
A11: 6 | B11: 목(木) | C11: 중화 | D11: 평(平) | E11: =INDEX(작성안내!$C$37:$C$41,1) | F11: =INDEX(작성안내!$C$37:$C$41,MATCH("수",작성안내!$A$37:$A$41,0)) | G11: =INDEX(작성안내!$C$37:$C$41,MATCH("금",작성안내!$A$37:$A$41,0)) | H11: =IF(TRIM(SUBSTITUTE(SUBSTITUTE(SUBSTITUTE(T(INDEX(B_강약진단!$D$6:$D$8,MATCH("mid",B_강약진단!$A$6:$A$8,0)))&" "&T(INDEX(A_용신선언!$D$6:$D$8,MATCH("mid",A_용신선언!$A$6:$A$8,0)))&" "&T(INDEX(D_부적처방!$D$6:$D$10,1)),"{용신}",$E11),"{희신}",$F11),"{기신}",$G11))="","(아직 문구가 채워지지 않았습니다)",TRIM(SUBSTITUTE(SUBSTITUTE(SUBSTITUTE(T(INDEX(B_강약진단!$D$6:$D$8,MATCH("mid",B_강약진단!$A$6:$A$8,0)))&" "&T(INDEX(A_용신선언!$D$6:$D$8,MATCH("mid",A_용신선언!$A$6:$A$8,0)))&" "&T(INDEX(D_부적처방!$D$6:$D$10,1)),"{용신}",$E11),"{희신}",$F11),"{기신}",$G11)))
A12: 7 | B12: 목(木) | C12: 신약 | D12: 한(寒) | E12: =INDEX(작성안내!$C$37:$C$41,1) | F12: =INDEX(작성안내!$C$37:$C$41,MATCH("수",작성안내!$A$37:$A$41,0)) | G12: =INDEX(작성안내!$C$37:$C$41,MATCH("금",작성안내!$A$37:$A$41,0)) | H12: =IF(TRIM(SUBSTITUTE(SUBSTITUTE(SUBSTITUTE(T(INDEX(B_강약진단!$D$6:$D$8,MATCH("weak",B_강약진단!$A$6:$A$8,0)))&" "&T(INDEX(A_용신선언!$D$6:$D$8,MATCH("weak",A_용신선언!$A$6:$A$8,0)))&" "&T(INDEX(C_조후보정!$D$6:$D$7,MATCH("cold",C_조후보정!$A$6:$A$7,0)))&" "&T(INDEX(D_부적처방!$D$6:$D$10,1)),"{용신}",$E12),"{희신}",$F12),"{기신}",$G12))="","(아직 문구가 채워지지 않았습니다)",TRIM(SUBSTITUTE(SUBSTITUTE(SUBSTITUTE(T(INDEX(B_강약진단!$D$6:$D$8,MATCH("weak",B_강약진단!$A$6:$A$8,0)))&" "&T(INDEX(A_용신선언!$D$6:$D$8,MATCH("weak",A_용신선언!$A$6:$A$8,0)))&" "&T(INDEX(C_조후보정!$D$6:$D$7,MATCH("cold",C_조후보정!$A$6:$A$7,0)))&" "&T(INDEX(D_부적처방!$D$6:$D$10,1)),"{용신}",$E12),"{희신}",$F12),"{기신}",$G12)))
A13: 8 | B13: 목(木) | C13: 신약 | D13: 열(熱) | E13: =INDEX(작성안내!$C$37:$C$41,1) | F13: =INDEX(작성안내!$C$37:$C$41,MATCH("수",작성안내!$A$37:$A$41,0)) | G13: =INDEX(작성안내!$C$37:$C$41,MATCH("금",작성안내!$A$37:$A$41,0)) | H13: =IF(TRIM(SUBSTITUTE(SUBSTITUTE(SUBSTITUTE(T(INDEX(B_강약진단!$D$6:$D$8,MATCH("weak",B_강약진단!$A$6:$A$8,0)))&" "&T(INDEX(A_용신선언!$D$6:$D$8,MATCH("weak",A_용신선언!$A$6:$A$8,0)))&" "&T(INDEX(C_조후보정!$D$6:$D$7,MATCH("hot",C_조후보정!$A$6:$A$7,0)))&" "&T(INDEX(D_부적처방!$D$6:$D$10,1)),"{용신}",$E13),"{희신}",$F13),"{기신}",$G13))="","(아직 문구가 채워지지 않았습니다)",TRIM(SUBSTITUTE(SUBSTITUTE(SUBSTITUTE(T(INDEX(B_강약진단!$D$6:$D$8,MATCH("weak",B_강약진단!$A$6:$A$8,0)))&" "&T(INDEX(A_용신선언!$D$6:$D$8,MATCH("weak",A_용신선언!$A$6:$A$8,0)))&" "&T(INDEX(C_조후보정!$D$6:$D$7,MATCH("hot",C_조후보정!$A$6:$A$7,0)))&" "&T(INDEX(D_부적처방!$D$6:$D$10,1)),"{용신}",$E13),"{희신}",$F13),"{기신}",$G13)))
A14: 9 | B14: 목(木) | C14: 신약 | D14: 평(平) | E14: =INDEX(작성안내!$C$37:$C$41,1) | F14: =INDEX(작성안내!$C$37:$C$41,MATCH("수",작성안내!$A$37:$A$41,0)) | G14: =INDEX(작성안내!$C$37:$C$41,MATCH("금",작성안내!$A$37:$A$41,0)) | H14: =IF(TRIM(SUBSTITUTE(SUBSTITUTE(SUBSTITUTE(T(INDEX(B_강약진단!$D$6:$D$8,MATCH("weak",B_강약진단!$A$6:$A$8,0)))&" "&T(INDEX(A_용신선언!$D$6:$D$8,MATCH("weak",A_용신선언!$A$6:$A$8,0)))&" "&T(INDEX(D_부적처방!$D$6:$D$10,1)),"{용신}",$E14),"{희신}",$F14),"{기신}",$G14))="","(아직 문구가 채워지지 않았습니다)",TRIM(SUBSTITUTE(SUBSTITUTE(SUBSTITUTE(T(INDEX(B_강약진단!$D$6:$D$8,MATCH("weak",B_강약진단!$A$6:$A$8,0)))&" "&T(INDEX(A_용신선언!$D$6:$D$8,MATCH("weak",A_용신선언!$A$6:$A$8,0)))&" "&T(INDEX(D_부적처방!$D$6:$D$10,1)),"{용신}",$E14),"{희신}",$F14),"{기신}",$G14)))
A15: 10 | B15: 화(火) | C15: 신강 | D15: 한(寒) | E15: =INDEX(작성안내!$C$37:$C$41,2) | F15: =INDEX(작성안내!$C$37:$C$41,MATCH("목",작성안내!$A$37:$A$41,0)) | G15: =INDEX(작성안내!$C$37:$C$41,MATCH("수",작성안내!$A$37:$A$41,0)) | H15: =IF(TRIM(SUBSTITUTE(SUBSTITUTE(SUBSTITUTE(T(INDEX(B_강약진단!$D$6:$D$8,MATCH("strong",B_강약진단!$A$6:$A$8,0)))&" "&T(INDEX(A_용신선언!$D$6:$D$8,MATCH("strong",A_용신선언!$A$6:$A$8,0)))&" "&T(INDEX(C_조후보정!$D$6:$D$7,MATCH("cold",C_조후보정!$A$6:$A$7,0)))&" "&T(INDEX(D_부적처방!$D$6:$D$10,2)),"{용신}",$E15),"{희신}",$F15),"{기신}",$G15))="","(아직 문구가 채워지지 않았습니다)",TRIM(SUBSTITUTE(SUBSTITUTE(SUBSTITUTE(T(INDEX(B_강약진단!$D$6:$D$8,MATCH("strong",B_강약진단!$A$6:$A$8,0)))&" "&T(INDEX(A_용신선언!$D$6:$D$8,MATCH("strong",A_용신선언!$A$6:$A$8,0)))&" "&T(INDEX(C_조후보정!$D$6:$D$7,MATCH("cold",C_조후보정!$A$6:$A$7,0)))&" "&T(INDEX(D_부적처방!$D$6:$D$10,2)),"{용신}",$E15),"{희신}",$F15),"{기신}",$G15)))
A16: 11 | B16: 화(火) | C16: 신강 | D16: 열(熱) | E16: =INDEX(작성안내!$C$37:$C$41,2) | F16: =INDEX(작성안내!$C$37:$C$41,MATCH("목",작성안내!$A$37:$A$41,0)) | G16: =INDEX(작성안내!$C$37:$C$41,MATCH("수",작성안내!$A$37:$A$41,0)) | H16: =IF(TRIM(SUBSTITUTE(SUBSTITUTE(SUBSTITUTE(T(INDEX(B_강약진단!$D$6:$D$8,MATCH("strong",B_강약진단!$A$6:$A$8,0)))&" "&T(INDEX(A_용신선언!$D$6:$D$8,MATCH("strong",A_용신선언!$A$6:$A$8,0)))&" "&T(INDEX(C_조후보정!$D$6:$D$7,MATCH("hot",C_조후보정!$A$6:$A$7,0)))&" "&T(INDEX(D_부적처방!$D$6:$D$10,2)),"{용신}",$E16),"{희신}",$F16),"{기신}",$G16))="","(아직 문구가 채워지지 않았습니다)",TRIM(SUBSTITUTE(SUBSTITUTE(SUBSTITUTE(T(INDEX(B_강약진단!$D$6:$D$8,MATCH("strong",B_강약진단!$A$6:$A$8,0)))&" "&T(INDEX(A_용신선언!$D$6:$D$8,MATCH("strong",A_용신선언!$A$6:$A$8,0)))&" "&T(INDEX(C_조후보정!$D$6:$D$7,MATCH("hot",C_조후보정!$A$6:$A$7,0)))&" "&T(INDEX(D_부적처방!$D$6:$D$10,2)),"{용신}",$E16),"{희신}",$F16),"{기신}",$G16)))
A17: 12 | B17: 화(火) | C17: 신강 | D17: 평(平) | E17: =INDEX(작성안내!$C$37:$C$41,2) | F17: =INDEX(작성안내!$C$37:$C$41,MATCH("목",작성안내!$A$37:$A$41,0)) | G17: =INDEX(작성안내!$C$37:$C$41,MATCH("수",작성안내!$A$37:$A$41,0)) | H17: =IF(TRIM(SUBSTITUTE(SUBSTITUTE(SUBSTITUTE(T(INDEX(B_강약진단!$D$6:$D$8,MATCH("strong",B_강약진단!$A$6:$A$8,0)))&" "&T(INDEX(A_용신선언!$D$6:$D$8,MATCH("strong",A_용신선언!$A$6:$A$8,0)))&" "&T(INDEX(D_부적처방!$D$6:$D$10,2)),"{용신}",$E17),"{희신}",$F17),"{기신}",$G17))="","(아직 문구가 채워지지 않았습니다)",TRIM(SUBSTITUTE(SUBSTITUTE(SUBSTITUTE(T(INDEX(B_강약진단!$D$6:$D$8,MATCH("strong",B_강약진단!$A$6:$A$8,0)))&" "&T(INDEX(A_용신선언!$D$6:$D$8,MATCH("strong",A_용신선언!$A$6:$A$8,0)))&" "&T(INDEX(D_부적처방!$D$6:$D$10,2)),"{용신}",$E17),"{희신}",$F17),"{기신}",$G17)))
A18: 13 | B18: 화(火) | C18: 중화 | D18: 한(寒) | E18: =INDEX(작성안내!$C$37:$C$41,2) | F18: =INDEX(작성안내!$C$37:$C$41,MATCH("목",작성안내!$A$37:$A$41,0)) | G18: =INDEX(작성안내!$C$37:$C$41,MATCH("수",작성안내!$A$37:$A$41,0)) | H18: =IF(TRIM(SUBSTITUTE(SUBSTITUTE(SUBSTITUTE(T(INDEX(B_강약진단!$D$6:$D$8,MATCH("mid",B_강약진단!$A$6:$A$8,0)))&" "&T(INDEX(A_용신선언!$D$6:$D$8,MATCH("mid",A_용신선언!$A$6:$A$8,0)))&" "&T(INDEX(C_조후보정!$D$6:$D$7,MATCH("cold",C_조후보정!$A$6:$A$7,0)))&" "&T(INDEX(D_부적처방!$D$6:$D$10,2)),"{용신}",$E18),"{희신}",$F18),"{기신}",$G18))="","(아직 문구가 채워지지 않았습니다)",TRIM(SUBSTITUTE(SUBSTITUTE(SUBSTITUTE(T(INDEX(B_강약진단!$D$6:$D$8,MATCH("mid",B_강약진단!$A$6:$A$8,0)))&" "&T(INDEX(A_용신선언!$D$6:$D$8,MATCH("mid",A_용신선언!$A$6:$A$8,0)))&" "&T(INDEX(C_조후보정!$D$6:$D$7,MATCH("cold",C_조후보정!$A$6:$A$7,0)))&" "&T(INDEX(D_부적처방!$D$6:$D$10,2)),"{용신}",$E18),"{희신}",$F18),"{기신}",$G18)))
A19: 14 | B19: 화(火) | C19: 중화 | D19: 열(熱) | E19: =INDEX(작성안내!$C$37:$C$41,2) | F19: =INDEX(작성안내!$C$37:$C$41,MATCH("목",작성안내!$A$37:$A$41,0)) | G19: =INDEX(작성안내!$C$37:$C$41,MATCH("수",작성안내!$A$37:$A$41,0)) | H19: =IF(TRIM(SUBSTITUTE(SUBSTITUTE(SUBSTITUTE(T(INDEX(B_강약진단!$D$6:$D$8,MATCH("mid",B_강약진단!$A$6:$A$8,0)))&" "&T(INDEX(A_용신선언!$D$6:$D$8,MATCH("mid",A_용신선언!$A$6:$A$8,0)))&" "&T(INDEX(C_조후보정!$D$6:$D$7,MATCH("hot",C_조후보정!$A$6:$A$7,0)))&" "&T(INDEX(D_부적처방!$D$6:$D$10,2)),"{용신}",$E19),"{희신}",$F19),"{기신}",$G19))="","(아직 문구가 채워지지 않았습니다)",TRIM(SUBSTITUTE(SUBSTITUTE(SUBSTITUTE(T(INDEX(B_강약진단!$D$6:$D$8,MATCH("mid",B_강약진단!$A$6:$A$8,0)))&" "&T(INDEX(A_용신선언!$D$6:$D$8,MATCH("mid",A_용신선언!$A$6:$A$8,0)))&" "&T(INDEX(C_조후보정!$D$6:$D$7,MATCH("hot",C_조후보정!$A$6:$A$7,0)))&" "&T(INDEX(D_부적처방!$D$6:$D$10,2)),"{용신}",$E19),"{희신}",$F19),"{기신}",$G19)))
A20: 15 | B20: 화(火) | C20: 중화 | D20: 평(平) | E20: =INDEX(작성안내!$C$37:$C$41,2) | F20: =INDEX(작성안내!$C$37:$C$41,MATCH("목",작성안내!$A$37:$A$41,0)) | G20: =INDEX(작성안내!$C$37:$C$41,MATCH("수",작성안내!$A$37:$A$41,0)) | H20: =IF(TRIM(SUBSTITUTE(SUBSTITUTE(SUBSTITUTE(T(INDEX(B_강약진단!$D$6:$D$8,MATCH("mid",B_강약진단!$A$6:$A$8,0)))&" "&T(INDEX(A_용신선언!$D$6:$D$8,MATCH("mid",A_용신선언!$A$6:$A$8,0)))&" "&T(INDEX(D_부적처방!$D$6:$D$10,2)),"{용신}",$E20),"{희신}",$F20),"{기신}",$G20))="","(아직 문구가 채워지지 않았습니다)",TRIM(SUBSTITUTE(SUBSTITUTE(SUBSTITUTE(T(INDEX(B_강약진단!$D$6:$D$8,MATCH("mid",B_강약진단!$A$6:$A$8,0)))&" "&T(INDEX(A_용신선언!$D$6:$D$8,MATCH("mid",A_용신선언!$A$6:$A$8,0)))&" "&T(INDEX(D_부적처방!$D$6:$D$10,2)),"{용신}",$E20),"{희신}",$F20),"{기신}",$G20)))
A21: 16 | B21: 화(火) | C21: 신약 | D21: 한(寒) | E21: =INDEX(작성안내!$C$37:$C$41,2) | F21: =INDEX(작성안내!$C$37:$C$41,MATCH("목",작성안내!$A$37:$A$41,0)) | G21: =INDEX(작성안내!$C$37:$C$41,MATCH("수",작성안내!$A$37:$A$41,0)) | H21: =IF(TRIM(SUBSTITUTE(SUBSTITUTE(SUBSTITUTE(T(INDEX(B_강약진단!$D$6:$D$8,MATCH("weak",B_강약진단!$A$6:$A$8,0)))&" "&T(INDEX(A_용신선언!$D$6:$D$8,MATCH("weak",A_용신선언!$A$6:$A$8,0)))&" "&T(INDEX(C_조후보정!$D$6:$D$7,MATCH("cold",C_조후보정!$A$6:$A$7,0)))&" "&T(INDEX(D_부적처방!$D$6:$D$10,2)),"{용신}",$E21),"{희신}",$F21),"{기신}",$G21))="","(아직 문구가 채워지지 않았습니다)",TRIM(SUBSTITUTE(SUBSTITUTE(SUBSTITUTE(T(INDEX(B_강약진단!$D$6:$D$8,MATCH("weak",B_강약진단!$A$6:$A$8,0)))&" "&T(INDEX(A_용신선언!$D$6:$D$8,MATCH("weak",A_용신선언!$A$6:$A$8,0)))&" "&T(INDEX(C_조후보정!$D$6:$D$7,MATCH("cold",C_조후보정!$A$6:$A$7,0)))&" "&T(INDEX(D_부적처방!$D$6:$D$10,2)),"{용신}",$E21),"{희신}",$F21),"{기신}",$G21)))
A22: 17 | B22: 화(火) | C22: 신약 | D22: 열(熱) | E22: =INDEX(작성안내!$C$37:$C$41,2) | F22: =INDEX(작성안내!$C$37:$C$41,MATCH("목",작성안내!$A$37:$A$41,0)) | G22: =INDEX(작성안내!$C$37:$C$41,MATCH("수",작성안내!$A$37:$A$41,0)) | H22: =IF(TRIM(SUBSTITUTE(SUBSTITUTE(SUBSTITUTE(T(INDEX(B_강약진단!$D$6:$D$8,MATCH("weak",B_강약진단!$A$6:$A$8,0)))&" "&T(INDEX(A_용신선언!$D$6:$D$8,MATCH("weak",A_용신선언!$A$6:$A$8,0)))&" "&T(INDEX(C_조후보정!$D$6:$D$7,MATCH("hot",C_조후보정!$A$6:$A$7,0)))&" "&T(INDEX(D_부적처방!$D$6:$D$10,2)),"{용신}",$E22),"{희신}",$F22),"{기신}",$G22))="","(아직 문구가 채워지지 않았습니다)",TRIM(SUBSTITUTE(SUBSTITUTE(SUBSTITUTE(T(INDEX(B_강약진단!$D$6:$D$8,MATCH("weak",B_강약진단!$A$6:$A$8,0)))&" "&T(INDEX(A_용신선언!$D$6:$D$8,MATCH("weak",A_용신선언!$A$6:$A$8,0)))&" "&T(INDEX(C_조후보정!$D$6:$D$7,MATCH("hot",C_조후보정!$A$6:$A$7,0)))&" "&T(INDEX(D_부적처방!$D$6:$D$10,2)),"{용신}",$E22),"{희신}",$F22),"{기신}",$G22)))
A23: 18 | B23: 화(火) | C23: 신약 | D23: 평(平) | E23: =INDEX(작성안내!$C$37:$C$41,2) | F23: =INDEX(작성안내!$C$37:$C$41,MATCH("목",작성안내!$A$37:$A$41,0)) | G23: =INDEX(작성안내!$C$37:$C$41,MATCH("수",작성안내!$A$37:$A$41,0)) | H23: =IF(TRIM(SUBSTITUTE(SUBSTITUTE(SUBSTITUTE(T(INDEX(B_강약진단!$D$6:$D$8,MATCH("weak",B_강약진단!$A$6:$A$8,0)))&" "&T(INDEX(A_용신선언!$D$6:$D$8,MATCH("weak",A_용신선언!$A$6:$A$8,0)))&" "&T(INDEX(D_부적처방!$D$6:$D$10,2)),"{용신}",$E23),"{희신}",$F23),"{기신}",$G23))="","(아직 문구가 채워지지 않았습니다)",TRIM(SUBSTITUTE(SUBSTITUTE(SUBSTITUTE(T(INDEX(B_강약진단!$D$6:$D$8,MATCH("weak",B_강약진단!$A$6:$A$8,0)))&" "&T(INDEX(A_용신선언!$D$6:$D$8,MATCH("weak",A_용신선언!$A$6:$A$8,0)))&" "&T(INDEX(D_부적처방!$D$6:$D$10,2)),"{용신}",$E23),"{희신}",$F23),"{기신}",$G23)))
A24: 19 | B24: 토(土) | C24: 신강 | D24: 한(寒) | E24: =INDEX(작성안내!$C$37:$C$41,3) | F24: =INDEX(작성안내!$C$37:$C$41,MATCH("화",작성안내!$A$37:$A$41,0)) | G24: =INDEX(작성안내!$C$37:$C$41,MATCH("목",작성안내!$A$37:$A$41,0)) | H24: =IF(TRIM(SUBSTITUTE(SUBSTITUTE(SUBSTITUTE(T(INDEX(B_강약진단!$D$6:$D$8,MATCH("strong",B_강약진단!$A$6:$A$8,0)))&" "&T(INDEX(A_용신선언!$D$6:$D$8,MATCH("strong",A_용신선언!$A$6:$A$8,0)))&" "&T(INDEX(C_조후보정!$D$6:$D$7,MATCH("cold",C_조후보정!$A$6:$A$7,0)))&" "&T(INDEX(D_부적처방!$D$6:$D$10,3)),"{용신}",$E24),"{희신}",$F24),"{기신}",$G24))="","(아직 문구가 채워지지 않았습니다)",TRIM(SUBSTITUTE(SUBSTITUTE(SUBSTITUTE(T(INDEX(B_강약진단!$D$6:$D$8,MATCH("strong",B_강약진단!$A$6:$A$8,0)))&" "&T(INDEX(A_용신선언!$D$6:$D$8,MATCH("strong",A_용신선언!$A$6:$A$8,0)))&" "&T(INDEX(C_조후보정!$D$6:$D$7,MATCH("cold",C_조후보정!$A$6:$A$7,0)))&" "&T(INDEX(D_부적처방!$D$6:$D$10,3)),"{용신}",$E24),"{희신}",$F24),"{기신}",$G24)))
A25: 20 | B25: 토(土) | C25: 신강 | D25: 열(熱) | E25: =INDEX(작성안내!$C$37:$C$41,3) | F25: =INDEX(작성안내!$C$37:$C$41,MATCH("화",작성안내!$A$37:$A$41,0)) | G25: =INDEX(작성안내!$C$37:$C$41,MATCH("목",작성안내!$A$37:$A$41,0)) | H25: =IF(TRIM(SUBSTITUTE(SUBSTITUTE(SUBSTITUTE(T(INDEX(B_강약진단!$D$6:$D$8,MATCH("strong",B_강약진단!$A$6:$A$8,0)))&" "&T(INDEX(A_용신선언!$D$6:$D$8,MATCH("strong",A_용신선언!$A$6:$A$8,0)))&" "&T(INDEX(C_조후보정!$D$6:$D$7,MATCH("hot",C_조후보정!$A$6:$A$7,0)))&" "&T(INDEX(D_부적처방!$D$6:$D$10,3)),"{용신}",$E25),"{희신}",$F25),"{기신}",$G25))="","(아직 문구가 채워지지 않았습니다)",TRIM(SUBSTITUTE(SUBSTITUTE(SUBSTITUTE(T(INDEX(B_강약진단!$D$6:$D$8,MATCH("strong",B_강약진단!$A$6:$A$8,0)))&" "&T(INDEX(A_용신선언!$D$6:$D$8,MATCH("strong",A_용신선언!$A$6:$A$8,0)))&" "&T(INDEX(C_조후보정!$D$6:$D$7,MATCH("hot",C_조후보정!$A$6:$A$7,0)))&" "&T(INDEX(D_부적처방!$D$6:$D$10,3)),"{용신}",$E25),"{희신}",$F25),"{기신}",$G25)))
A26: 21 | B26: 토(土) | C26: 신강 | D26: 평(平) | E26: =INDEX(작성안내!$C$37:$C$41,3) | F26: =INDEX(작성안내!$C$37:$C$41,MATCH("화",작성안내!$A$37:$A$41,0)) | G26: =INDEX(작성안내!$C$37:$C$41,MATCH("목",작성안내!$A$37:$A$41,0)) | H26: =IF(TRIM(SUBSTITUTE(SUBSTITUTE(SUBSTITUTE(T(INDEX(B_강약진단!$D$6:$D$8,MATCH("strong",B_강약진단!$A$6:$A$8,0)))&" "&T(INDEX(A_용신선언!$D$6:$D$8,MATCH("strong",A_용신선언!$A$6:$A$8,0)))&" "&T(INDEX(D_부적처방!$D$6:$D$10,3)),"{용신}",$E26),"{희신}",$F26),"{기신}",$G26))="","(아직 문구가 채워지지 않았습니다)",TRIM(SUBSTITUTE(SUBSTITUTE(SUBSTITUTE(T(INDEX(B_강약진단!$D$6:$D$8,MATCH("strong",B_강약진단!$A$6:$A$8,0)))&" "&T(INDEX(A_용신선언!$D$6:$D$8,MATCH("strong",A_용신선언!$A$6:$A$8,0)))&" "&T(INDEX(D_부적처방!$D$6:$D$10,3)),"{용신}",$E26),"{희신}",$F26),"{기신}",$G26)))
A27: 22 | B27: 토(土) | C27: 중화 | D27: 한(寒) | E27: =INDEX(작성안내!$C$37:$C$41,3) | F27: =INDEX(작성안내!$C$37:$C$41,MATCH("화",작성안내!$A$37:$A$41,0)) | G27: =INDEX(작성안내!$C$37:$C$41,MATCH("목",작성안내!$A$37:$A$41,0)) | H27: =IF(TRIM(SUBSTITUTE(SUBSTITUTE(SUBSTITUTE(T(INDEX(B_강약진단!$D$6:$D$8,MATCH("mid",B_강약진단!$A$6:$A$8,0)))&" "&T(INDEX(A_용신선언!$D$6:$D$8,MATCH("mid",A_용신선언!$A$6:$A$8,0)))&" "&T(INDEX(C_조후보정!$D$6:$D$7,MATCH("cold",C_조후보정!$A$6:$A$7,0)))&" "&T(INDEX(D_부적처방!$D$6:$D$10,3)),"{용신}",$E27),"{희신}",$F27),"{기신}",$G27))="","(아직 문구가 채워지지 않았습니다)",TRIM(SUBSTITUTE(SUBSTITUTE(SUBSTITUTE(T(INDEX(B_강약진단!$D$6:$D$8,MATCH("mid",B_강약진단!$A$6:$A$8,0)))&" "&T(INDEX(A_용신선언!$D$6:$D$8,MATCH("mid",A_용신선언!$A$6:$A$8,0)))&" "&T(INDEX(C_조후보정!$D$6:$D$7,MATCH("cold",C_조후보정!$A$6:$A$7,0)))&" "&T(INDEX(D_부적처방!$D$6:$D$10,3)),"{용신}",$E27),"{희신}",$F27),"{기신}",$G27)))
A28: 23 | B28: 토(土) | C28: 중화 | D28: 열(熱) | E28: =INDEX(작성안내!$C$37:$C$41,3) | F28: =INDEX(작성안내!$C$37:$C$41,MATCH("화",작성안내!$A$37:$A$41,0)) | G28: =INDEX(작성안내!$C$37:$C$41,MATCH("목",작성안내!$A$37:$A$41,0)) | H28: =IF(TRIM(SUBSTITUTE(SUBSTITUTE(SUBSTITUTE(T(INDEX(B_강약진단!$D$6:$D$8,MATCH("mid",B_강약진단!$A$6:$A$8,0)))&" "&T(INDEX(A_용신선언!$D$6:$D$8,MATCH("mid",A_용신선언!$A$6:$A$8,0)))&" "&T(INDEX(C_조후보정!$D$6:$D$7,MATCH("hot",C_조후보정!$A$6:$A$7,0)))&" "&T(INDEX(D_부적처방!$D$6:$D$10,3)),"{용신}",$E28),"{희신}",$F28),"{기신}",$G28))="","(아직 문구가 채워지지 않았습니다)",TRIM(SUBSTITUTE(SUBSTITUTE(SUBSTITUTE(T(INDEX(B_강약진단!$D$6:$D$8,MATCH("mid",B_강약진단!$A$6:$A$8,0)))&" "&T(INDEX(A_용신선언!$D$6:$D$8,MATCH("mid",A_용신선언!$A$6:$A$8,0)))&" "&T(INDEX(C_조후보정!$D$6:$D$7,MATCH("hot",C_조후보정!$A$6:$A$7,0)))&" "&T(INDEX(D_부적처방!$D$6:$D$10,3)),"{용신}",$E28),"{희신}",$F28),"{기신}",$G28)))
A29: 24 | B29: 토(土) | C29: 중화 | D29: 평(平) | E29: =INDEX(작성안내!$C$37:$C$41,3) | F29: =INDEX(작성안내!$C$37:$C$41,MATCH("화",작성안내!$A$37:$A$41,0)) | G29: =INDEX(작성안내!$C$37:$C$41,MATCH("목",작성안내!$A$37:$A$41,0)) | H29: =IF(TRIM(SUBSTITUTE(SUBSTITUTE(SUBSTITUTE(T(INDEX(B_강약진단!$D$6:$D$8,MATCH("mid",B_강약진단!$A$6:$A$8,0)))&" "&T(INDEX(A_용신선언!$D$6:$D$8,MATCH("mid",A_용신선언!$A$6:$A$8,0)))&" "&T(INDEX(D_부적처방!$D$6:$D$10,3)),"{용신}",$E29),"{희신}",$F29),"{기신}",$G29))="","(아직 문구가 채워지지 않았습니다)",TRIM(SUBSTITUTE(SUBSTITUTE(SUBSTITUTE(T(INDEX(B_강약진단!$D$6:$D$8,MATCH("mid",B_강약진단!$A$6:$A$8,0)))&" "&T(INDEX(A_용신선언!$D$6:$D$8,MATCH("mid",A_용신선언!$A$6:$A$8,0)))&" "&T(INDEX(D_부적처방!$D$6:$D$10,3)),"{용신}",$E29),"{희신}",$F29),"{기신}",$G29)))
A30: 25 | B30: 토(土) | C30: 신약 | D30: 한(寒) | E30: =INDEX(작성안내!$C$37:$C$41,3) | F30: =INDEX(작성안내!$C$37:$C$41,MATCH("화",작성안내!$A$37:$A$41,0)) | G30: =INDEX(작성안내!$C$37:$C$41,MATCH("목",작성안내!$A$37:$A$41,0)) | H30: =IF(TRIM(SUBSTITUTE(SUBSTITUTE(SUBSTITUTE(T(INDEX(B_강약진단!$D$6:$D$8,MATCH("weak",B_강약진단!$A$6:$A$8,0)))&" "&T(INDEX(A_용신선언!$D$6:$D$8,MATCH("weak",A_용신선언!$A$6:$A$8,0)))&" "&T(INDEX(C_조후보정!$D$6:$D$7,MATCH("cold",C_조후보정!$A$6:$A$7,0)))&" "&T(INDEX(D_부적처방!$D$6:$D$10,3)),"{용신}",$E30),"{희신}",$F30),"{기신}",$G30))="","(아직 문구가 채워지지 않았습니다)",TRIM(SUBSTITUTE(SUBSTITUTE(SUBSTITUTE(T(INDEX(B_강약진단!$D$6:$D$8,MATCH("weak",B_강약진단!$A$6:$A$8,0)))&" "&T(INDEX(A_용신선언!$D$6:$D$8,MATCH("weak",A_용신선언!$A$6:$A$8,0)))&" "&T(INDEX(C_조후보정!$D$6:$D$7,MATCH("cold",C_조후보정!$A$6:$A$7,0)))&" "&T(INDEX(D_부적처방!$D$6:$D$10,3)),"{용신}",$E30),"{희신}",$F30),"{기신}",$G30)))
A31: 26 | B31: 토(土) | C31: 신약 | D31: 열(熱) | E31: =INDEX(작성안내!$C$37:$C$41,3) | F31: =INDEX(작성안내!$C$37:$C$41,MATCH("화",작성안내!$A$37:$A$41,0)) | G31: =INDEX(작성안내!$C$37:$C$41,MATCH("목",작성안내!$A$37:$A$41,0)) | H31: =IF(TRIM(SUBSTITUTE(SUBSTITUTE(SUBSTITUTE(T(INDEX(B_강약진단!$D$6:$D$8,MATCH("weak",B_강약진단!$A$6:$A$8,0)))&" "&T(INDEX(A_용신선언!$D$6:$D$8,MATCH("weak",A_용신선언!$A$6:$A$8,0)))&" "&T(INDEX(C_조후보정!$D$6:$D$7,MATCH("hot",C_조후보정!$A$6:$A$7,0)))&" "&T(INDEX(D_부적처방!$D$6:$D$10,3)),"{용신}",$E31),"{희신}",$F31),"{기신}",$G31))="","(아직 문구가 채워지지 않았습니다)",TRIM(SUBSTITUTE(SUBSTITUTE(SUBSTITUTE(T(INDEX(B_강약진단!$D$6:$D$8,MATCH("weak",B_강약진단!$A$6:$A$8,0)))&" "&T(INDEX(A_용신선언!$D$6:$D$8,MATCH("weak",A_용신선언!$A$6:$A$8,0)))&" "&T(INDEX(C_조후보정!$D$6:$D$7,MATCH("hot",C_조후보정!$A$6:$A$7,0)))&" "&T(INDEX(D_부적처방!$D$6:$D$10,3)),"{용신}",$E31),"{희신}",$F31),"{기신}",$G31)))
A32: 27 | B32: 토(土) | C32: 신약 | D32: 평(平) | E32: =INDEX(작성안내!$C$37:$C$41,3) | F32: =INDEX(작성안내!$C$37:$C$41,MATCH("화",작성안내!$A$37:$A$41,0)) | G32: =INDEX(작성안내!$C$37:$C$41,MATCH("목",작성안내!$A$37:$A$41,0)) | H32: =IF(TRIM(SUBSTITUTE(SUBSTITUTE(SUBSTITUTE(T(INDEX(B_강약진단!$D$6:$D$8,MATCH("weak",B_강약진단!$A$6:$A$8,0)))&" "&T(INDEX(A_용신선언!$D$6:$D$8,MATCH("weak",A_용신선언!$A$6:$A$8,0)))&" "&T(INDEX(D_부적처방!$D$6:$D$10,3)),"{용신}",$E32),"{희신}",$F32),"{기신}",$G32))="","(아직 문구가 채워지지 않았습니다)",TRIM(SUBSTITUTE(SUBSTITUTE(SUBSTITUTE(T(INDEX(B_강약진단!$D$6:$D$8,MATCH("weak",B_강약진단!$A$6:$A$8,0)))&" "&T(INDEX(A_용신선언!$D$6:$D$8,MATCH("weak",A_용신선언!$A$6:$A$8,0)))&" "&T(INDEX(D_부적처방!$D$6:$D$10,3)),"{용신}",$E32),"{희신}",$F32),"{기신}",$G32)))
A33: 28 | B33: 금(金) | C33: 신강 | D33: 한(寒) | E33: =INDEX(작성안내!$C$37:$C$41,4) | F33: =INDEX(작성안내!$C$37:$C$41,MATCH("토",작성안내!$A$37:$A$41,0)) | G33: =INDEX(작성안내!$C$37:$C$41,MATCH("화",작성안내!$A$37:$A$41,0)) | H33: =IF(TRIM(SUBSTITUTE(SUBSTITUTE(SUBSTITUTE(T(INDEX(B_강약진단!$D$6:$D$8,MATCH("strong",B_강약진단!$A$6:$A$8,0)))&" "&T(INDEX(A_용신선언!$D$6:$D$8,MATCH("strong",A_용신선언!$A$6:$A$8,0)))&" "&T(INDEX(C_조후보정!$D$6:$D$7,MATCH("cold",C_조후보정!$A$6:$A$7,0)))&" "&T(INDEX(D_부적처방!$D$6:$D$10,4)),"{용신}",$E33),"{희신}",$F33),"{기신}",$G33))="","(아직 문구가 채워지지 않았습니다)",TRIM(SUBSTITUTE(SUBSTITUTE(SUBSTITUTE(T(INDEX(B_강약진단!$D$6:$D$8,MATCH("strong",B_강약진단!$A$6:$A$8,0)))&" "&T(INDEX(A_용신선언!$D$6:$D$8,MATCH("strong",A_용신선언!$A$6:$A$8,0)))&" "&T(INDEX(C_조후보정!$D$6:$D$7,MATCH("cold",C_조후보정!$A$6:$A$7,0)))&" "&T(INDEX(D_부적처방!$D$6:$D$10,4)),"{용신}",$E33),"{희신}",$F33),"{기신}",$G33)))
A34: 29 | B34: 금(金) | C34: 신강 | D34: 열(熱) | E34: =INDEX(작성안내!$C$37:$C$41,4) | F34: =INDEX(작성안내!$C$37:$C$41,MATCH("토",작성안내!$A$37:$A$41,0)) | G34: =INDEX(작성안내!$C$37:$C$41,MATCH("화",작성안내!$A$37:$A$41,0)) | H34: =IF(TRIM(SUBSTITUTE(SUBSTITUTE(SUBSTITUTE(T(INDEX(B_강약진단!$D$6:$D$8,MATCH("strong",B_강약진단!$A$6:$A$8,0)))&" "&T(INDEX(A_용신선언!$D$6:$D$8,MATCH("strong",A_용신선언!$A$6:$A$8,0)))&" "&T(INDEX(C_조후보정!$D$6:$D$7,MATCH("hot",C_조후보정!$A$6:$A$7,0)))&" "&T(INDEX(D_부적처방!$D$6:$D$10,4)),"{용신}",$E34),"{희신}",$F34),"{기신}",$G34))="","(아직 문구가 채워지지 않았습니다)",TRIM(SUBSTITUTE(SUBSTITUTE(SUBSTITUTE(T(INDEX(B_강약진단!$D$6:$D$8,MATCH("strong",B_강약진단!$A$6:$A$8,0)))&" "&T(INDEX(A_용신선언!$D$6:$D$8,MATCH("strong",A_용신선언!$A$6:$A$8,0)))&" "&T(INDEX(C_조후보정!$D$6:$D$7,MATCH("hot",C_조후보정!$A$6:$A$7,0)))&" "&T(INDEX(D_부적처방!$D$6:$D$10,4)),"{용신}",$E34),"{희신}",$F34),"{기신}",$G34)))
A35: 30 | B35: 금(金) | C35: 신강 | D35: 평(平) | E35: =INDEX(작성안내!$C$37:$C$41,4) | F35: =INDEX(작성안내!$C$37:$C$41,MATCH("토",작성안내!$A$37:$A$41,0)) | G35: =INDEX(작성안내!$C$37:$C$41,MATCH("화",작성안내!$A$37:$A$41,0)) | H35: =IF(TRIM(SUBSTITUTE(SUBSTITUTE(SUBSTITUTE(T(INDEX(B_강약진단!$D$6:$D$8,MATCH("strong",B_강약진단!$A$6:$A$8,0)))&" "&T(INDEX(A_용신선언!$D$6:$D$8,MATCH("strong",A_용신선언!$A$6:$A$8,0)))&" "&T(INDEX(D_부적처방!$D$6:$D$10,4)),"{용신}",$E35),"{희신}",$F35),"{기신}",$G35))="","(아직 문구가 채워지지 않았습니다)",TRIM(SUBSTITUTE(SUBSTITUTE(SUBSTITUTE(T(INDEX(B_강약진단!$D$6:$D$8,MATCH("strong",B_강약진단!$A$6:$A$8,0)))&" "&T(INDEX(A_용신선언!$D$6:$D$8,MATCH("strong",A_용신선언!$A$6:$A$8,0)))&" "&T(INDEX(D_부적처방!$D$6:$D$10,4)),"{용신}",$E35),"{희신}",$F35),"{기신}",$G35)))
A36: 31 | B36: 금(金) | C36: 중화 | D36: 한(寒) | E36: =INDEX(작성안내!$C$37:$C$41,4) | F36: =INDEX(작성안내!$C$37:$C$41,MATCH("토",작성안내!$A$37:$A$41,0)) | G36: =INDEX(작성안내!$C$37:$C$41,MATCH("화",작성안내!$A$37:$A$41,0)) | H36: =IF(TRIM(SUBSTITUTE(SUBSTITUTE(SUBSTITUTE(T(INDEX(B_강약진단!$D$6:$D$8,MATCH("mid",B_강약진단!$A$6:$A$8,0)))&" "&T(INDEX(A_용신선언!$D$6:$D$8,MATCH("mid",A_용신선언!$A$6:$A$8,0)))&" "&T(INDEX(C_조후보정!$D$6:$D$7,MATCH("cold",C_조후보정!$A$6:$A$7,0)))&" "&T(INDEX(D_부적처방!$D$6:$D$10,4)),"{용신}",$E36),"{희신}",$F36),"{기신}",$G36))="","(아직 문구가 채워지지 않았습니다)",TRIM(SUBSTITUTE(SUBSTITUTE(SUBSTITUTE(T(INDEX(B_강약진단!$D$6:$D$8,MATCH("mid",B_강약진단!$A$6:$A$8,0)))&" "&T(INDEX(A_용신선언!$D$6:$D$8,MATCH("mid",A_용신선언!$A$6:$A$8,0)))&" "&T(INDEX(C_조후보정!$D$6:$D$7,MATCH("cold",C_조후보정!$A$6:$A$7,0)))&" "&T(INDEX(D_부적처방!$D$6:$D$10,4)),"{용신}",$E36),"{희신}",$F36),"{기신}",$G36)))
A37: 32 | B37: 금(金) | C37: 중화 | D37: 열(熱) | E37: =INDEX(작성안내!$C$37:$C$41,4) | F37: =INDEX(작성안내!$C$37:$C$41,MATCH("토",작성안내!$A$37:$A$41,0)) | G37: =INDEX(작성안내!$C$37:$C$41,MATCH("화",작성안내!$A$37:$A$41,0)) | H37: =IF(TRIM(SUBSTITUTE(SUBSTITUTE(SUBSTITUTE(T(INDEX(B_강약진단!$D$6:$D$8,MATCH("mid",B_강약진단!$A$6:$A$8,0)))&" "&T(INDEX(A_용신선언!$D$6:$D$8,MATCH("mid",A_용신선언!$A$6:$A$8,0)))&" "&T(INDEX(C_조후보정!$D$6:$D$7,MATCH("hot",C_조후보정!$A$6:$A$7,0)))&" "&T(INDEX(D_부적처방!$D$6:$D$10,4)),"{용신}",$E37),"{희신}",$F37),"{기신}",$G37))="","(아직 문구가 채워지지 않았습니다)",TRIM(SUBSTITUTE(SUBSTITUTE(SUBSTITUTE(T(INDEX(B_강약진단!$D$6:$D$8,MATCH("mid",B_강약진단!$A$6:$A$8,0)))&" "&T(INDEX(A_용신선언!$D$6:$D$8,MATCH("mid",A_용신선언!$A$6:$A$8,0)))&" "&T(INDEX(C_조후보정!$D$6:$D$7,MATCH("hot",C_조후보정!$A$6:$A$7,0)))&" "&T(INDEX(D_부적처방!$D$6:$D$10,4)),"{용신}",$E37),"{희신}",$F37),"{기신}",$G37)))
A38: 33 | B38: 금(金) | C38: 중화 | D38: 평(平) | E38: =INDEX(작성안내!$C$37:$C$41,4) | F38: =INDEX(작성안내!$C$37:$C$41,MATCH("토",작성안내!$A$37:$A$41,0)) | G38: =INDEX(작성안내!$C$37:$C$41,MATCH("화",작성안내!$A$37:$A$41,0)) | H38: =IF(TRIM(SUBSTITUTE(SUBSTITUTE(SUBSTITUTE(T(INDEX(B_강약진단!$D$6:$D$8,MATCH("mid",B_강약진단!$A$6:$A$8,0)))&" "&T(INDEX(A_용신선언!$D$6:$D$8,MATCH("mid",A_용신선언!$A$6:$A$8,0)))&" "&T(INDEX(D_부적처방!$D$6:$D$10,4)),"{용신}",$E38),"{희신}",$F38),"{기신}",$G38))="","(아직 문구가 채워지지 않았습니다)",TRIM(SUBSTITUTE(SUBSTITUTE(SUBSTITUTE(T(INDEX(B_강약진단!$D$6:$D$8,MATCH("mid",B_강약진단!$A$6:$A$8,0)))&" "&T(INDEX(A_용신선언!$D$6:$D$8,MATCH("mid",A_용신선언!$A$6:$A$8,0)))&" "&T(INDEX(D_부적처방!$D$6:$D$10,4)),"{용신}",$E38),"{희신}",$F38),"{기신}",$G38)))
A39: 34 | B39: 금(金) | C39: 신약 | D39: 한(寒) | E39: =INDEX(작성안내!$C$37:$C$41,4) | F39: =INDEX(작성안내!$C$37:$C$41,MATCH("토",작성안내!$A$37:$A$41,0)) | G39: =INDEX(작성안내!$C$37:$C$41,MATCH("화",작성안내!$A$37:$A$41,0)) | H39: =IF(TRIM(SUBSTITUTE(SUBSTITUTE(SUBSTITUTE(T(INDEX(B_강약진단!$D$6:$D$8,MATCH("weak",B_강약진단!$A$6:$A$8,0)))&" "&T(INDEX(A_용신선언!$D$6:$D$8,MATCH("weak",A_용신선언!$A$6:$A$8,0)))&" "&T(INDEX(C_조후보정!$D$6:$D$7,MATCH("cold",C_조후보정!$A$6:$A$7,0)))&" "&T(INDEX(D_부적처방!$D$6:$D$10,4)),"{용신}",$E39),"{희신}",$F39),"{기신}",$G39))="","(아직 문구가 채워지지 않았습니다)",TRIM(SUBSTITUTE(SUBSTITUTE(SUBSTITUTE(T(INDEX(B_강약진단!$D$6:$D$8,MATCH("weak",B_강약진단!$A$6:$A$8,0)))&" "&T(INDEX(A_용신선언!$D$6:$D$8,MATCH("weak",A_용신선언!$A$6:$A$8,0)))&" "&T(INDEX(C_조후보정!$D$6:$D$7,MATCH("cold",C_조후보정!$A$6:$A$7,0)))&" "&T(INDEX(D_부적처방!$D$6:$D$10,4)),"{용신}",$E39),"{희신}",$F39),"{기신}",$G39)))
A40: 35 | B40: 금(金) | C40: 신약 | D40: 열(熱) | E40: =INDEX(작성안내!$C$37:$C$41,4) | F40: =INDEX(작성안내!$C$37:$C$41,MATCH("토",작성안내!$A$37:$A$41,0)) | G40: =INDEX(작성안내!$C$37:$C$41,MATCH("화",작성안내!$A$37:$A$41,0)) | H40: =IF(TRIM(SUBSTITUTE(SUBSTITUTE(SUBSTITUTE(T(INDEX(B_강약진단!$D$6:$D$8,MATCH("weak",B_강약진단!$A$6:$A$8,0)))&" "&T(INDEX(A_용신선언!$D$6:$D$8,MATCH("weak",A_용신선언!$A$6:$A$8,0)))&" "&T(INDEX(C_조후보정!$D$6:$D$7,MATCH("hot",C_조후보정!$A$6:$A$7,0)))&" "&T(INDEX(D_부적처방!$D$6:$D$10,4)),"{용신}",$E40),"{희신}",$F40),"{기신}",$G40))="","(아직 문구가 채워지지 않았습니다)",TRIM(SUBSTITUTE(SUBSTITUTE(SUBSTITUTE(T(INDEX(B_강약진단!$D$6:$D$8,MATCH("weak",B_강약진단!$A$6:$A$8,0)))&" "&T(INDEX(A_용신선언!$D$6:$D$8,MATCH("weak",A_용신선언!$A$6:$A$8,0)))&" "&T(INDEX(C_조후보정!$D$6:$D$7,MATCH("hot",C_조후보정!$A$6:$A$7,0)))&" "&T(INDEX(D_부적처방!$D$6:$D$10,4)),"{용신}",$E40),"{희신}",$F40),"{기신}",$G40)))
A41: 36 | B41: 금(金) | C41: 신약 | D41: 평(平) | E41: =INDEX(작성안내!$C$37:$C$41,4) | F41: =INDEX(작성안내!$C$37:$C$41,MATCH("토",작성안내!$A$37:$A$41,0)) | G41: =INDEX(작성안내!$C$37:$C$41,MATCH("화",작성안내!$A$37:$A$41,0)) | H41: =IF(TRIM(SUBSTITUTE(SUBSTITUTE(SUBSTITUTE(T(INDEX(B_강약진단!$D$6:$D$8,MATCH("weak",B_강약진단!$A$6:$A$8,0)))&" "&T(INDEX(A_용신선언!$D$6:$D$8,MATCH("weak",A_용신선언!$A$6:$A$8,0)))&" "&T(INDEX(D_부적처방!$D$6:$D$10,4)),"{용신}",$E41),"{희신}",$F41),"{기신}",$G41))="","(아직 문구가 채워지지 않았습니다)",TRIM(SUBSTITUTE(SUBSTITUTE(SUBSTITUTE(T(INDEX(B_강약진단!$D$6:$D$8,MATCH("weak",B_강약진단!$A$6:$A$8,0)))&" "&T(INDEX(A_용신선언!$D$6:$D$8,MATCH("weak",A_용신선언!$A$6:$A$8,0)))&" "&T(INDEX(D_부적처방!$D$6:$D$10,4)),"{용신}",$E41),"{희신}",$F41),"{기신}",$G41)))
...
